Exception on /accountant_dashboard/cash_book_report1 [GET]
Traceback (most recent call last):
  File "C:\Users\user\Desktop\Weba1\venv\lib\site-packages\flask\app.py", line 2073, in wsgi_app
    response = self.full_dispatch_request()
  File "C:\Users\user\Desktop\Weba1\venv\lib\site-packages\flask\app.py", line 1518, in full_dispatch_request
    rv = self.handle_user_exception(e)
  File "C:\Users\user\Desktop\Weba1\venv\lib\site-packages\flask\app.py", line 1516, in full_dispatch_request
    rv = self.dispatch_request()
  File "C:\Users\user\Desktop\Weba1\venv\lib\site-packages\flask\app.py", line 1502, in dispatch_request
    return self.ensure_sync(self.view_functions[rule.endpoint])(**req.view_args)
  File "C:\Users\user\Desktop\Weba1\venv\lib\site-packages\flask_login\utils.py", line 272, in decorated_view
    return func(*args, **kwargs)
  File "C:\Users\user\Desktop\Weba1\app.py", line 378, in cash_book_report1
    return render_template("cash_book11.html", balance=balance,
  File "C:\Users\user\Desktop\Weba1\venv\lib\site-packages\flask\templating.py", line 147, in render_template
    return _render(
  File "C:\Users\user\Desktop\Weba1\venv\lib\site-packages\flask\templating.py", line 128, in _render
    rv = template.render(context)
  File "C:\Users\user\Desktop\Weba1\venv\lib\site-packages\jinja2\environment.py", line 1291, in render
    self.environment.handle_exception()
  File "C:\Users\user\Desktop\Weba1\venv\lib\site-packages\jinja2\environment.py", line 925, in handle_exception
    raise rewrite_traceback_stack(source=source)
  File "C:\Users\user\Desktop\Weba1\templates\cash_book11.html", line 2, in top-level template code
    {% extends "bootstrap.html" %}
  File "C:\Users\user\Desktop\Weba1\templates\bootstrap.html", line 34, in top-level template code
    {% block content%}
  File "C:\Users\user\Desktop\Weba1\templates\cash_book11.html", line 158, in block 'content'
    <td>{{date[loop.index-1]}}</td>
  File "C:\Users\user\Desktop\Weba1\venv\lib\site-packages\jinja2\environment.py", line 455, in getitem
    return obj[argument]
jinja2.exceptions.UndefinedError: 'date' is undefined
Exception on /register_user [POST]
Traceback (most recent call last):
  File "C:\Users\user\Desktop\Weba1\venv\lib\site-packages\sqlalchemy\engine\base.py", line 1802, in _execute_context
    self.dialect.do_execute(
  File "C:\Users\user\Desktop\Weba1\venv\lib\site-packages\sqlalchemy\engine\default.py", line 732, in do_execute
    cursor.execute(statement, parameters)
sqlite3.OperationalError: no such table: user

The above exception was the direct cause of the following exception:

Traceback (most recent call last):
  File "C:\Users\user\Desktop\Weba1\venv\lib\site-packages\flask\app.py", line 2073, in wsgi_app
    response = self.full_dispatch_request()
  File "C:\Users\user\Desktop\Weba1\venv\lib\site-packages\flask\app.py", line 1518, in full_dispatch_request
    rv = self.handle_user_exception(e)
  File "C:\Users\user\Desktop\Weba1\venv\lib\site-packages\flask\app.py", line 1516, in full_dispatch_request
    rv = self.dispatch_request()
  File "C:\Users\user\Desktop\Weba1\venv\lib\site-packages\flask\app.py", line 1502, in dispatch_request
    return self.ensure_sync(self.view_functions[rule.endpoint])(**req.view_args)
  File "C:\Users\user\Desktop\Weba1\app.py", line 88, in register_user
    if form.validate_on_submit():
  File "C:\Users\user\Desktop\Weba1\venv\lib\site-packages\flask_wtf\form.py", line 86, in validate_on_submit
    return self.is_submitted() and self.validate()
  File "C:\Users\user\Desktop\Weba1\venv\lib\site-packages\wtforms\form.py", line 329, in validate
    return super().validate(extra)
  File "C:\Users\user\Desktop\Weba1\venv\lib\site-packages\wtforms\form.py", line 146, in validate
    if not field.validate(self, extra):
  File "C:\Users\user\Desktop\Weba1\venv\lib\site-packages\wtforms\fields\core.py", line 242, in validate
    stop_validation = self._run_validation_chain(form, chain)
  File "C:\Users\user\Desktop\Weba1\venv\lib\site-packages\wtforms\fields\core.py", line 262, in _run_validation_chain
    validator(form, self)
  File "C:\Users\user\Desktop\Weba1\app.py", line 835, in validate_email
    user = User.query.filter_by(email=email.data).first()
  File "C:\Users\user\Desktop\Weba1\venv\lib\site-packages\sqlalchemy\orm\query.py", line 2810, in first
    return self.limit(1)._iter().first()
  File "C:\Users\user\Desktop\Weba1\venv\lib\site-packages\sqlalchemy\orm\query.py", line 2894, in _iter
    result = self.session.execute(
  File "C:\Users\user\Desktop\Weba1\venv\lib\site-packages\sqlalchemy\orm\session.py", line 1692, in execute
    result = conn._execute_20(statement, params or {}, execution_options)
  File "C:\Users\user\Desktop\Weba1\venv\lib\site-packages\sqlalchemy\engine\base.py", line 1614, in _execute_20
    return meth(self, args_10style, kwargs_10style, execution_options)
  File "C:\Users\user\Desktop\Weba1\venv\lib\site-packages\sqlalchemy\sql\elements.py", line 325, in _execute_on_connection
    return connection._execute_clauseelement(
  File "C:\Users\user\Desktop\Weba1\venv\lib\site-packages\sqlalchemy\engine\base.py", line 1481, in _execute_clauseelement
    ret = self._execute_context(
  File "C:\Users\user\Desktop\Weba1\venv\lib\site-packages\sqlalchemy\engine\base.py", line 1845, in _execute_context
    self._handle_dbapi_exception(
  File "C:\Users\user\Desktop\Weba1\venv\lib\site-packages\sqlalchemy\engine\base.py", line 2026, in _handle_dbapi_exception
    util.raise_(
  File "C:\Users\user\Desktop\Weba1\venv\lib\site-packages\sqlalchemy\util\compat.py", line 207, in raise_
    raise exception
  File "C:\Users\user\Desktop\Weba1\venv\lib\site-packages\sqlalchemy\engine\base.py", line 1802, in _execute_context
    self.dialect.do_execute(
  File "C:\Users\user\Desktop\Weba1\venv\lib\site-packages\sqlalchemy\engine\default.py", line 732, in do_execute
    cursor.execute(statement, parameters)
sqlalchemy.exc.OperationalError: (sqlite3.OperationalError) no such table: user
[SQL: SELECT user.id AS user_id, user.date AS user_date, user.username AS user_username, user.email AS user_email, user.password AS user_password, user.is_admin AS user_is_admin, user.function AS user_function, user.approval AS user_approval 
FROM user 
WHERE user.email = ?
 LIMIT ? OFFSET ?]
[parameters: ('kuminewton@gmail.com', 1, 0)]
(Background on this error at: https://sqlalche.me/e/14/e3q8)
